<?xml version="1.0" encoding="utf-8"?>
<robot name="manip_desc">

  <link name="base_link">
    <visual>
      <origin xyz="0 0 0" rpy="0 0 0"/>
      <geometry>
        <mesh filename="meshes/base_link.stl" scale="0.001 0.001 0.001"/>
      </geometry>
    </visual>
  </link>

  <link name="r1_link">
    <visual>
      <origin xyz="0 0 0" rpy="0 0 0"/>
      <geometry>
        <mesh filename="meshes/r1_link.stl" scale="0.001 0.001 0.001"/>
      </geometry>
    </visual>
  </link>

  <joint name="r1_joint" type="revolute">
    <origin xyz="0 0.2235 0" rpy="0 0 0"/>
    <parent link="base_link"/>
    <child link="r1_link"/>
    <axis xyz="0 -1 0"/>
    <limit lower="-3.1416" upper="3.1416" effort="1" velocity="1"/>
  </joint>

  <link name="r2_link">
    <visual>
      <origin xyz="0 0 0" rpy="0 0 0"/>
      <geometry>
        <mesh filename="meshes/r2_link.stl" scale="0.001 0.001 0.001"/>
      </geometry>
    </visual>
  </link>

  <joint name="r2_joint" type="revolute">
    <origin xyz="-0.0058329 0.05 0.047644" rpy="0 0 0"/>
    <parent link="r1_link"/>
    <child link="r2_link"/>
    <axis xyz="0.12152 0 -0.99259"/>
    <limit lower="-3.1416" upper="3.1416" effort="1" velocity="1"/>
  </joint>

  <link name="p3_link">
    <visual>
      <origin xyz="0 0 0" rpy="0 0 0"/>
      <geometry>
        <mesh filename="meshes/p3_link.stl" scale="0.001 0.001 0.001"/>
      </geometry>
    </visual>
  </link>

  <joint name="p3_joint" type="prismatic">
    <origin xyz="0.14517 0.061047 0.068146" rpy="0 0 0"/>
    <parent link="r2_link"/>
    <child link="p3_link"/>
    <axis xyz="-0.9208 -0.3716 -0.1127"/>
    <limit lower="0.0" upper="0.1" effort="0.1" velocity="0.1"/>
  </joint>

  <link name="r4_link">
    <visual>
      <origin xyz="0 0 0" rpy="0 0 0"/>
      <geometry>
        <mesh filename="meshes/r4_link.stl" scale="0.001 0.001 0.001"/>
      </geometry>
    </visual>
  </link>

  <joint name="r4_joint" type="revolute">
    <origin xyz="0.1594 0.064338 0.019515" rpy="0 0 0"/>
    <parent link="p3_link"/>
    <child link="r4_link"/>
    <axis xyz="-0.9208 -0.3716 -0.1127"/>
    <limit lower="-3.1416" upper="3.1416" effort="1" velocity="1"/>
  </joint>

  <link name="r5_link">
    <visual>
      <origin xyz="0 0 0" rpy="0 0 0"/>
      <geometry>
        <mesh filename="meshes/r5_link.stl" scale="0.001 0.001 0.001"/>
      </geometry>
    </visual>
  </link>

  <joint name="r5_joint" type="revolute">
    <origin xyz="0.059599 -0.0025077 -0.035295" rpy="0 0 0"/>
    <parent link="r4_link"/>
    <child link="r5_link"/>
    <axis xyz="-0.28185 0.43964 0.85281"/>
    <limit lower="-3.1416" upper="3.1416" effort="1" velocity="1"/>
  </joint>

</robot>
