<?xml version="1.0" encoding="utf-8"?>
<!-- This URDF was automatically created by SolidWorks to URDF Exporter! Originally created by Stephen Brawner (brawner@gmail.com) 
     Commit Version: 1.6.0-4-g7f85cfe  Build Version: 1.6.7995.38578
     For more information, please see http://wiki.ros.org/sw_urdf_exporter -->
<robot
  name="manip_desc">
  <link
    name="base_link">
    <inertial>
      <origin
        xyz="2.2768E-18 0.08131 2.6829E-19"
        rpy="0 0 0" />
      <mass
        value="0.6413" />
      <inertia
        ixx="0.0035154"
        ixy="4.0891E-20"
        ixz="-8.1426E-22"
        iyy="0.00053532"
        iyz="7.3991E-20"
        izz="0.0035154" />
    </inertial>
    <visual>
      <origin
        xyz="0 0 0"
        rpy="0 0 0" />
      <geometry>
        <mesh
          filename="meshes/base_link.stl" />
      </geometry>
      <material
        name="">
        <color
          rgba="0.99608 0.99608 1 1" />
      </material>
    </visual>
    <collision>
      <origin
        xyz="0 0 0"
        rpy="0 0 0" />
      <geometry>
        <mesh
          filename="meshes/base_link.stl" />
      </geometry>
    </collision>
  </link>
  <link
    name="R1_Link">
    <inertial>
      <origin
        xyz="-0.0049734 0.045914 0.040612"
        rpy="0 0 0" />
      <mass
        value="0.095716" />
      <inertia
        ixx="0.00010623"
        ixy="2.1067E-06"
        ixz="6.6784E-06"
        iyy="9.9208E-05"
        iyz="-1.7206E-05"
        izz="5.2491E-05" />
    </inertial>
    <visual>
      <origin
        xyz="0 0 0"
        rpy="0 0 0" />
      <geometry>
        <mesh
          filename="meshes/r1_link.stl" />
      </geometry>
      <material
        name="">
        <color
          rgba="0.99608 0.99608 1 1" />
      </material>
    </visual>
    <collision>
      <origin
        xyz="0 0 0"
        rpy="0 0 0" />
      <geometry>
        <mesh
          filename="meshes/r1_link.stl" />
      </geometry>
    </collision>
  </link>
  <joint
    name="r1_Joint"
    type="continuous">
    <origin
      xyz="0 0.2235 0"
      rpy="0 0 0" />
    <parent
      link="base_link" />
    <child
      link="r1_link" />
    <axis
      xyz="0 -1 0" />
  </joint>
  <link
    name="r2_link">
    <inertial>
      <origin
        xyz="0.093002 0.039843 0.058495"
        rpy="0 0 0" />
      <mass
        value="0.11904" />
      <inertia
        ixx="0.00021241"
        ixy="-0.00025335"
        ixz="-0.00011512"
        iyy="0.00073258"
        iyz="-4.7056E-05"
        izz="0.00080853" />
    </inertial>
    <visual>
      <origin
        xyz="0 0 0"
        rpy="0 0 0" />
      <geometry>
        <mesh
          filename="meshes/r2_link.stl" />
      </geometry>
      <material
        name="">
        <color
          rgba="0.99608 0.99608 1 1" />
      </material>
    </visual>
    <collision>
      <origin
        xyz="0 0 0"
        rpy="0 0 0" />
      <geometry>
        <mesh
          filename="meshes/r2_link.stl" />
      </geometry>
    </collision>
  </link>
  <joint
    name="r2_Joint"
    type="continuous">
    <origin
      xyz="-0.0058329 0.05 0.047644"
      rpy="0 0 0" />
    <parent
      link="r1_Link" />
    <child
      link="r2_Link" />
    <axis
      xyz="0.12152 0 -0.99259" />
  </joint>
  <link
    name="P3_Link">
    <inertial>
      <origin
        xyz="0.092139 0.03719 0.01128"
        rpy="0 0 0" />
      <mass
        value="0.39209" />
      <inertia
        ixx="0.0003099"
        ixy="-0.00042551"
        ixz="-0.00012907"
        iyy="0.0011924"
        iyz="-5.2094E-05"
        izz="0.0013483" />
    </inertial>
    <visual>
      <origin
        xyz="0 0 0"
        rpy="0 0 0" />
      <geometry>
        <mesh
          filename="meshes/p3_link.stl" />
      </geometry>
      <material
        name="">
        <color
          rgba="0.99608 0.99608 1 1" />
      </material>
    </visual>
    <collision>
      <origin
        xyz="0 0 0"
        rpy="0 0 0" />
      <geometry>
        <mesh
          filename="meshes/p3_link.stl" />
      </geometry>
    </collision>
  </link>
  <joint
    name="p3_joint"
    type="prismatic">
    <origin
      xyz="0.14517 0.061047 0.068146"
      rpy="0 0 0" />
    <parent
      link="r2_link" />
    <child
      link="p3_link" />
    <axis
      xyz="-0.92139 -0.3719 -0.1128" />
    <limit
      lower="-0.1"
      upper="0.1"
      effort="0.1"
      velocity="0.1" />
  </joint>
  <link
    name="r4_link">
    <inertial>
      <origin
        xyz="0.053838 -0.00091398 -0.029713"
        rpy="0 0 0" />
      <mass
        value="0.095715" />
      <inertia
        ixx="8.6989E-05"
        ixy="9.3797E-06"
        ixz="2.5565E-05"
        iyy="0.00010093"
        iyz="-1.4733E-05"
        izz="7.0009E-05" />
    </inertial>
    <visual>
      <origin
        xyz="0 0 0"
        rpy="0 0 0" />
      <geometry>
        <mesh
          filename="meshes/r4_link.stl" />
      </geometry>
      <material
        name="">
        <color
          rgba="0.99608 0.99608 1 1" />
      </material>
    </visual>
    <collision>
      <origin
        xyz="0 0 0"
        rpy="0 0 0" />
      <geometry>
        <mesh
          filename="meshes/r4_link.stl" />
      </geometry>
    </collision>
  </link>
  <joint
    name="r4_joint"
    type="continuous">
    <origin
      xyz="0.1594 0.064338 0.019515"
      rpy="0 0 0" />
    <parent
      link="p3_link" />
    <child
      link="r4_link" />
    <axis
      xyz="-0.92139 -0.3719 -0.1128" />
  </joint>
  <link
    name="r5_link">
    <inertial>
      <origin
        xyz="-0.0013606 0.011757 -0.060348"
        rpy="0 0 0" />
      <mass
        value="0.095722" />
      <inertia
        ixx="0.00010308"
        ixy="9.6027E-06"
        ixz="-1.0775E-05"
        iyy="8.3682E-05"
        iyz="2.705E-05"
        izz="7.1175E-05" />
    </inertial>
    <visual>
      <origin
        xyz="0 0 0"
        rpy="0 0 0" />
      <geometry>
        <mesh
          filename="meshes/r5_link.stl" />
      </geometry>
      <material
        name="">
        <color
          rgba="0.99608 0.99608 1 1" />
      </material>
    </visual>
    <collision>
      <origin
        xyz="0 0 0"
        rpy="0 0 0" />
      <geometry>
        <mesh
          filename="meshes/r5_link.stl" />
      </geometry>
    </collision>
  </link>
  <joint
    name="r5_joint"
    type="continuous">
    <origin
      xyz="0.059599 -0.0025077 -0.035295"
      rpy="0 0 0" />
    <parent
      link="r4_link" />
    <child
      link="r5_link" />
    <axis
      xyz="-0.28185 0.43964 0.85281" />
  </joint>
  <link
    name="base_camera_link">
    <inertial>
      <origin
        xyz="-0.011197 0.025014 -0.016596"
        rpy="0 0 0" />
      <mass
        value="0.10321" />
      <inertia
        ixx="4.1894E-05"
        ixy="-2.4726E-06"
        ixz="-1.637E-06"
        iyy="4.5218E-05"
        iyz="2.0107E-06"
        izz="4.9126E-05" />
    </inertial>
    <visual>
      <origin
        xyz="0 0 0"
        rpy="0 0 0" />
      <geometry>
        <mesh
          filename="meshes/base_camera_link.stl" />
      </geometry>
      <material
        name="">
        <color
          rgba="0.99608 0.99608 1 1" />
      </material>
    </visual>
    <collision>
      <origin
        xyz="0 0 0"
        rpy="0 0 0" />
      <geometry>
        <mesh
          filename="meshes/base_camera_link.stl" />
      </geometry>
    </collision>
  </link>
  <joint
    name="base_camera_joint"
    type="fixed">
    <origin
      xyz="-0.0061779 0.023301 -0.072684"
      rpy="0 0 0" />
    <parent
      link="r5_link" />
    <child
      link="base_camera_link" />
    <axis
      xyz="0 0 0" />
  </joint>
  <link
    name="camera_link">
    <inertial>
      <origin
        xyz="-0.0049011 0.010949 -0.007264"
        rpy="0 0 0" />
      <mass
        value="0.061767" />
      <inertia
        ixx="1.345E-05"
        ixy="-9.7918E-06"
        ixz="-1.3948E-06"
        iyy="2.8311E-05"
        iyz="-8.4788E-07"
        izz="3.292E-05" />
    </inertial>
    <visual>
      <origin
        xyz="0 0 0"
        rpy="0 0 0" />
      <geometry>
        <mesh
          filename="meshes/camera_link.stl" />
      </geometry>
      <material
        name="">
        <color
          rgba="0.99608 0.99608 1 1" />
      </material>
    </visual>
    <collision>
      <origin
        xyz="0 0 0"
        rpy="0 0 0" />
      <geometry>
        <mesh
          filename="meshes/camera_link.stl" />
      </geometry>
    </collision>
  </link>
  <joint
    name="camera_joint"
    type="fixed">
    <origin
      xyz="-0.019222 0.04294 -0.028489"
      rpy="0 0 0" />
    <parent
      link="base_camera_link" />
    <child
      link="camera_link" />
    <axis
      xyz="0 0 0" />
  </joint>
</robot>
